[2019-11-29 19:47:17,281] {/app/calibre-web/cps/web.py:188} INFO - Starting Calibre Web...
[2019-11-29 19:47:17,654] {/app/calibre-web/cps/server.py:84} INFO - Starting Gevent server
[2019-11-29 20:17:27,048] {/app/calibre-web/cps/server.py:130} INFO - Performing shutdown of Calibre-Web
[2019-11-29 20:20:43,313] {/app/calibre-web/cps/web.py:188} INFO - Starting Calibre Web...
[2019-11-29 20:20:43,844] {/app/calibre-web/cps/server.py:84} INFO - Starting Gevent server
[2019-11-29 20:39:26,168] {/app/calibre-web/cps/web.py:2061} INFO - Elements-of-Group-Theory-for-Physicists - Unknown
[2019-11-29 20:39:26,304] {/app/calibre-web/cps/web.py:2061} INFO - Elements-of-Group-Theory-for-Physicists - Unknown
[2019-11-29 20:39:26,319] {/app/calibre-web/cps/web.py:2061} INFO - Elements-of-Group-Theory-for-Physicists - Unknown
[2019-11-29 20:40:31,822] {/app/calibre-web/cps/server.py:130} INFO - Performing shutdown of Calibre-Web
[2019-11-29 20:47:03,378] {/app/calibre-web/cps/web.py:188} INFO - Starting Calibre Web...
[2019-11-29 20:47:03,853] {/app/calibre-web/cps/server.py:84} INFO - Starting Gevent server
[2019-12-02 12:57:47,013] {/usr/local/lib/python3.6/dist-packages/flask/app.py:1891} ERROR - Exception on /admin/user/10 [GET]
Traceback (most recent call last):
  File "/usr/local/lib/python3.6/dist-packages/flask/app.py", line 2446, in wsgi_app
    response = self.full_dispatch_request()
  File "/usr/local/lib/python3.6/dist-packages/flask/app.py", line 1951, in full_dispatch_request
    rv = self.handle_user_exception(e)
  File "/usr/local/lib/python3.6/dist-packages/flask/app.py", line 1820, in handle_user_exception
    reraise(exc_type, exc_value, tb)
  File "/usr/local/lib/python3.6/dist-packages/flask/_compat.py", line 39, in reraise
    raise value
  File "/usr/local/lib/python3.6/dist-packages/flask/app.py", line 1949, in full_dispatch_request
    rv = self.dispatch_request()
  File "/usr/local/lib/python3.6/dist-packages/flask/app.py", line 1935, in dispatch_request
    return self.view_functions[rule.endpoint](**req.view_args)
  File "/usr/local/lib/python3.6/dist-packages/flask_login/utils.py", line 261, in decorated_view
    return func(*args, **kwargs)
  File "/app/calibre-web/cps/web.py", line 461, in inner
    return f(*args, **kwargs)
  File "/app/calibre-web/cps/web.py", line 3247, in edit_user
    for book in content.downloads:
AttributeError: 'NoneType' object has no attribute 'downloads'
[2019-12-02 12:57:51,097] {/usr/local/lib/python3.6/dist-packages/flask/app.py:1891} ERROR - Exception on /admin/user/9 [GET]
Traceback (most recent call last):
  File "/usr/local/lib/python3.6/dist-packages/flask/app.py", line 2446, in wsgi_app
    response = self.full_dispatch_request()
  File "/usr/local/lib/python3.6/dist-packages/flask/app.py", line 1951, in full_dispatch_request
    rv = self.handle_user_exception(e)
  File "/usr/local/lib/python3.6/dist-packages/flask/app.py", line 1820, in handle_user_exception
    reraise(exc_type, exc_value, tb)
  File "/usr/local/lib/python3.6/dist-packages/flask/_compat.py", line 39, in reraise
    raise value
  File "/usr/local/lib/python3.6/dist-packages/flask/app.py", line 1949, in full_dispatch_request
    rv = self.dispatch_request()
  File "/usr/local/lib/python3.6/dist-packages/flask/app.py", line 1935, in dispatch_request
    return self.view_functions[rule.endpoint](**req.view_args)
  File "/usr/local/lib/python3.6/dist-packages/flask_login/utils.py", line 261, in decorated_view
    return func(*args, **kwargs)
  File "/app/calibre-web/cps/web.py", line 461, in inner
    return f(*args, **kwargs)
  File "/app/calibre-web/cps/web.py", line 3247, in edit_user
    for book in content.downloads:
AttributeError: 'NoneType' object has no attribute 'downloads'
[2019-12-05 11:25:59,187] {/app/calibre-web/cps/web.py:2301} INFO - Login failed for user "testd" IP-adress: ::ffff:192.168.192.1
[2019-12-05 11:26:10,905] {/app/calibre-web/cps/web.py:2301} INFO - Login failed for user "testd" IP-adress: ::ffff:192.168.192.1
[2019-12-05 18:43:26,254] {/app/calibre-web/cps/web.py:2301} INFO - Login failed for user "bro" IP-adress: ::ffff:192.168.192.1
[2019-12-05 22:21:04,344] {/app/calibre-web/cps/web.py:2061} INFO - Elements-of-Group-Theory-for-Physicists - A W Joshi
[2019-12-05 22:21:04,516] {/app/calibre-web/cps/web.py:2061} INFO - Elements-of-Group-Theory-for-Physicists - A W Joshi
[2019-12-05 22:21:04,627] {/app/calibre-web/cps/web.py:2061} INFO - Elements-of-Group-Theory-for-Physicists - A W Joshi
[2019-12-05 22:21:04,754] {/app/calibre-web/cps/web.py:2061} INFO - Elements-of-Group-Theory-for-Physicists - A W Joshi
[2019-12-11 20:46:46,157] {/app/calibre-web/cps/server.py:130} INFO - Performing shutdown of Calibre-Web
